Workbook
Name _FilterDatabase_0: 'Přehled dne'!$A$3:$AJ$3
Name _FilterDatabase_0_0: 'Přehled dne'!$A$3:$AJ$3
Name _FilterDatabase_0_0_0: 'Přehled dne'!$A$3:$AJ$3
Name _FilterDatabase_0_0_0_0: 'Přehled dne'!$A$3:$AJ$3
Name _FilterDatabase_0_0_0_0_0: 'Přehled dne'!$A$3:$AJ$3
Name _FilterDatabase_0: 'Fiskalizované doklady'!$A$3:$AK$3
Name _FilterDatabase_0_0: 'Fiskalizované doklady'!$A$3:$AK$3
Name _FilterDatabase_0_0_0: 'Fiskalizované doklady'!$A$3:$AK$3
Name _FilterDatabase_0_0_0_0: 'Fiskalizované doklady'!$A$3:$AK$3
Name _FilterDatabase_0_0_0_0_0: 'Fiskalizované doklady'!$A$3:$AK$3
Name _FilterDatabase_0: 'Položky dokladů'!$A$3:$AC$3
Name _FilterDatabase_0_0: 'Položky dokladů'!$A$3:$AC$3
Name _FilterDatabase_0_0_0: 'Položky dokladů'!$A$3:$AC$3
Name _FilterDatabase_0_0_0_0: 'Položky dokladů'!$A$3:$AC$3
Name _FilterDatabase_0_0_0_0_0: 'Položky dokladů'!$A$3:$AC$3
Name _FilterDatabase_0: 'Zrušené položky'!$A$3:$Y$3
Name _FilterDatabase_0_0: 'Zrušené položky'!$A$3:$Y$3
Name _FilterDatabase_0_0_0: 'Zrušené položky'!$A$3:$Y$3
Name _FilterDatabase_0_0_0_0: 'Zrušené položky'!$A$3:$Y$3
Name _FilterDatabase_0_0_0_0_0: 'Zrušené položky'!$A$3:$Y$3

Sheet SOUHRN
A1: OBDOBÍ OD: | B1: 46132
A2: OBDOBÍ DO: | B2: 46132
A3: FIRMA: | B3: RAPO BRNO, s.r.o.
A4: DIČ: | B4: CZ60738677
A5: PROVOZOVNA: | B5: BALADA - Březinky
A6: ID PROVOZOVNY: | B6: 96
A7: ID POKLADNY: | B7: Více pokladen
A8: UŽIVATEL: | B8: Více uživatelů
A11: TRŽBY | B11: FISKALIZOVANÉ | C11: NEFISKALIZOVANÉ | D11: CELKEM | F11: STAV POKLADNY
A12: zdroj dat: | B12: záložka Fiskalizované doklady | C12: záložka Nefiskalizované doklady | D12: součet | F12: zdroj dat: | G12: záložka Přehled dne
B13: =IF(COUNTA('Fiskalizované doklady'!G4:G999932)=SUBTOTAL(103,'Fiskalizované doklady'!G4:G999932),"","Na datech záložky je nastaven filtr") | C13: =IF(COUNTA('Nefiskalizované doklady'!G1:G999994)=SUBTOTAL(103,'Nefiskalizované doklady'!G1:G999994),"","Na datech záložky je nastaven filtr") | G13: =IF(COUNTA('Přehled dne'!A4:A999990)=SUBTOTAL(103,'Přehled dne'!A4:A999990),"","Na datech záložky je nastaven filtr")
A14: TRŽBY CELKEM | B14: ='Fiskalizované doklady'!J2 -> 0 | C14: ='Nefiskalizované doklady'!J2 -> 92316.38 | D14: =B14+C14 -> 92316.38 | F14: POČÁTEČNÍ STAV K DATU | G14: 46132.015
A15: Poskytnuté slevy | B15: ='Fiskalizované doklady'!AL2 -> 0 | C15: ='Nefiskalizované doklady'!AF2 -> 1083.0861 | D15: =B15+C15 -> 1083.0861 | F15: Hotovost | G15: 0
A16: Zaokrouhlení | B16: ='Fiskalizované doklady'!M2 -> 0 | C16: ='Nefiskalizované doklady'!M2 -> 21.23 | D16: =B16+C16 -> 21.23 | F16: Stravenky | G16: 0
F17: Počáteční stav celkem | G17: =G15+G16 -> 0
A18: OBRATY
A19: Zboží bez DPH prodané | B19: ='Fiskalizované doklady'!S2 -> 0 | C19: ='Nefiskalizované doklady'!S2 -> 80438.671 | D19: =B19+C19 -> 80438.671 | F19: ÚHRADY
A20: Zboží bez DPH vrácené | B20: ='Fiskalizované doklady'!U2 -> 0 | C20: ='Nefiskalizované doklady'!U2 -> 0 | D20: =B20+C20 -> 0 | F20: Hotovost | G20: =D40 -> 38903
A21: Saldo prodeje bez DPH | B21: =B19+B20 -> 0 | C21: =C19+C20 -> 80438.671 | D21: =B21+C21 -> 80438.671 | F21: Stravenky | G21: =D41 -> 0
A22: Zboží s DPH prodané | B22: ='Fiskalizované doklady'!T2 -> 0 | C22: ='Nefiskalizované doklady'!T2 -> 92289.15 | D22: =B22+C22 -> 92289.15 | F22: Platby celkem | G22: =G20+G21 -> 38903
A23: Zboží s DPH vrácené | B23: ='Fiskalizované doklady'!V2 -> 0 | C23: ='Nefiskalizované doklady'!V2 -> 0 | D23: =B23+C23 -> 0
A24: Saldo prodeje s DPH | B24: =B22+B23 -> 0 | C24: =C22+C23 -> 92289.15 | D24: =B24+C24 -> 92289.15 | F24: CASHBACK
A25: Obaly prodané | B25: ='Fiskalizované doklady'!W2 -> 0 | C25: ='Nefiskalizované doklady'!W2 -> 75 | D25: =B25+C25 -> 75 | F25: Cashback | G25: ='Přehled dne'!AB2 -> 0
A26: Obaly vykoupené | B26: ='Fiskalizované doklady'!X2 -> 0 | C26: ='Nefiskalizované doklady'!X2 -> -69 | D26: =B26+C26 -> -69 | F26: CASHBACK celkem | G26: =G25 -> 0
A27: Saldo obalů | B27: =B25+B26 -> 0 | C27: =C25+C26 -> 6 | D27: =B27+C27 -> 6
A28: Zaokrouhlení | B28: ='Fiskalizované doklady'!Y2 -> 0 | C28: ='Nefiskalizované doklady'!Y2 -> 21.23 | D28: =B28+C28 -> 21.23 | F28: DOTACE A ODVODY
A29: kontrolní součet | B29: =B24+B27+B28 -> 0 | C29: =C24+C27+C28 -> 92316.38 | D29: =B29+C29 -> 92316.38 | F29: Dotace - hotovost | G29: ='Přehled dne'!AC2 -> 0
A30: DPH | F30: Dotace - stravenky | G30: ='Přehled dne'!AD2 -> 0
A31: Základ 21% | B31: ='Fiskalizované doklady'!N2 -> 0 | C31: ='Nefiskalizované doklady'!N2 -> 24403.425 | D31: =B31+C31 -> 24403.425 | F31: Odvody - hotovost | G31: ='Přehled dne'!AE2 -> 0
A32: Základ 12% | B32: ='Fiskalizované doklady'!O2 -> 0 | C32: ='Nefiskalizované doklady'!O2 -> 56035.246 | D32: =B32+C32 -> 56035.246 | F32: Odvody - stravenky | G32: ='Přehled dne'!AF2 -> 0
A33: Základ 0% | B33: ='Fiskalizované doklady'!P2 -> 0 | C33: ='Nefiskalizované doklady'!P2 -> 6 | D33: =B33+C33 -> 6 | F33: Dotace a odvody celkem | G33: =G29+G30+G31+G32 -> 0
A34: Základ celkem | B34: =SUM(B31:B33) -> 0 | C34: =SUM(C31:C33) -> 80444.671 | D34: =B34+C34 -> 80444.671
A35: DPH 21% | B35: ='Fiskalizované doklady'!Q2 -> 0 | C35: ='Nefiskalizované doklady'!Q2 -> 5125.0054 | D35: =B35+C35 -> 5125.0054 | F35: KONEČNÝ STAV K DATU | G35: 46132.836
A36: DPH 12% | B36: ='Fiskalizované doklady'!R2 -> 0 | C36: ='Nefiskalizované doklady'!R2 -> 6725.4739 | D36: =B36+C36 -> 6725.4739 | F36: Hotovost | G36: ='Přehled dne'!AH2 -> #VALUE!
A37: DPH celkem | B37: =SUM(B35:B36) -> 0 | C37: =SUM(C35:C36) -> 11850.479 | D37: =B37+C37 -> 11850.479 | F37: Stravenky | G37: ='Přehled dne'!AI2 -> #VALUE!
A38: kontrolní součet | B38: =B34+B37+B16 -> 0 | C38: =C34+C37+C16 -> 92316.38 | D38: =B38+C38 -> 92316.38 | F38: Konečný stav celkem | G38: =G36+G37 -> #VALUE!
A39: ÚHRADY | F39: kontrolní součet | G39: =G17+G22+G26+G33 -> 38903
A40: Hotovost | B40: ='Fiskalizované doklady'!Z2+'Fiskalizované doklady'!AE2 -> 0 | C40: ='Nefiskalizované doklady'!Z2+'Nefiskalizované doklady'!AE2 -> 38903 | D40: =B40+C40 -> 38903
A41: Stravenky | B41: ='Fiskalizované doklady'!AA2 -> 0 | C41: ='Nefiskalizované doklady'!AA2 -> 0 | D41: =B41+C41 -> 0
A42: Platební karta | B42: ='Fiskalizované doklady'!AB2+'Fiskalizované doklady'!AD2 -> 0 | C42: ='Nefiskalizované doklady'!AB2+'Nefiskalizované doklady'!AD2 -> 53413.38 | D42: =B42+C42 -> 53413.38
...

Sheet Přehled dne
A1: Datum a čas | B1: Akce | C1: Uživatel | D1: DIČ | E1: ID provozovny | F1: ID pokladny | G1: Číslo dokladu | H1: Tržba | L1: Dle sazeb DPH | Q1: Dle věcného rozlišení | X1: Finanční transakce | AG1: Konečný zůstatek pokladny | AK1: Poskytnuté slevy
H2: =SUBTOTAL(109,H4:H999856) -> 92316.38 | I2: =SUBTOTAL(109,I4:I999856) -> 80444.671 | J2: =SUBTOTAL(109,J4:J999856) -> 11850.479 | K2: =SUBTOTAL(109,K4:K999856) -> 21.23 | L2: =SUBTOTAL(109,L4:L999856) -> 24403.425 | M2: =SUBTOTAL(109,M4:M999856) -> 56035.246 | N2: =SUBTOTAL(109,N4:N999856) -> 6 | O2: =SUBTOTAL(109,O4:O999856) -> 5125.0054 | P2: =SUBTOTAL(109,P4:P999856) -> 6725.4739 | Q2: =SUBTOTAL(109,Q4:Q999938) -> 80438.671 | R2: =SUBTOTAL(109,R4:R999938) -> 92289.15 | S2: =SUBTOTAL(109,S4:S999938) -> 0 | T2: =SUBTOTAL(109,T4:T999938) -> 0 | U2: =SUBTOTAL(109,U4:U999938) -> 75 | V2: =SUBTOTAL(109,V4:V999938) -> -69 | W2: =SUBTOTAL(109,W4:W999938) -> 21.23 | X2: =SUBTOTAL(109,X4:X999938) -> 87217 | ... Z2: =SUBTOTAL(109,Z4:Z999938) -> 53413.38 | AB2: =SUBTOTAL(109,AB4:AB999938) -> 0 | AC2: =SUBTOTAL(109,AC4:AC999853) -> 0 | AD2: =SUBTOTAL(109,AD4:AD999853) -> 0 | AE2: =SUBTOTAL(109,AE4:AE999853) -> 0 | AF2: =SUBTOTAL(109,AF4:AF999853) -> 0 | AG2: =IF(SUBTOTAL(104,AG4:AG999853)=0,"Datum není k dispozici",SUBTOTAL(104,AG4:AG999853)) -> 46132.836 | AH2: =IFERROR(VLOOKUP(AG2,AG4:AH999990,2),"0 Kč") -> #VALUE! | AI2: =IFERROR(VLOOKUP(AH2,AH4:AI999990,2),"0 Kč") -> #VALUE! | AJ2: =AH2+AI2 -> #VALUE! | AK2: =SUBTOTAL(109,AK4:AK999853) -> 1083.0861
H3: Tržba celkem | I3: Základ DPH celkem | J3: DPH Celkem | K3: Zaokrouhlení | L3: Základ DPH 21% | M3: Základ DPH 12% | N3: Základ DPH 0% | O3: DPH 21% | P3: DPH 12% | Q3: Prodané zboží bez DPH | R3: Prodané zboží s DPH | S3: Vrácené zboží bez DPH | T3: Vrácené zboží s DPH | U3: Prodané obaly | V3: Vykoupené obaly | W3: Zaokrouhlení | X3: Úhrada hotovost | Y3: Úhrada stravenky | Z3: Platba platební kartou | AA3: Gastro konto | AB3: Cashback | AC3: Dotace hotovost | AD3: Dotace stravenky | AE3: Odvody hotovost | AF3: Odvody stravenky | AG3: K času | AH3: Hotovost | AI3: Stravenky | AJ3: Celkem | AK3: Sleva na pokladně
A4: 46132.015 | B4: Přihlášení | C4: profikasa | D4: CZ60738677 | E4: 96 | F4: Pokladna SCO2 | H4: 0 | I4: ==L4+M4+N4 -> FALSE | J4: ==O4+P4 -> FALSE | K4: ==IF(H4=I4+J4,0,W4) -> FALSE | L4: 0 | M4: 0 | N4: 0 | O4: 0 | P4: 0 | Q4: 0 | R4: 0 | S4: 0 | T4: 0 | U4: 0 | V4: 0 | W4: 0 | Y4: 0 | Z4: 0 | AA4: 0 | AB4: 0 | AC4: 0 | AD4: 0 | AE4: 0 | AF4: 0 | AG4: 46132.015 | AH4: 0 | AI4: 0 | AJ4: ==AH4+AI4 -> FALSE
A5: 46132.015 | B5: Převod | C5: převod z 19.04.2026 | E5: -1 | H5: 0 | I5: =L5+M5+N5 -> 0 | J5: =O5+P5 -> 0 | K5: =IF(H5=I5+J5,0,W5) -> 0 | L5: 0 | M5: 0 | N5: 0 | O5: 0 | P5: 0 | Q5: 0 | R5: 0 | S5: 0 | T5: 0 | U5: 0 | V5: 0 | W5: 0 | X5: 0 | Y5: 0 | Z5: 0 | AA5: 0 | AB5: 0 | AC5: 0 | AD5: 0 | AE5: 0 | AF5: 0 | AG5: 46132.015 | AH5: 0 | AI5: 0 | AJ5: =AH5+AI5 -> 0
A6: 46132.015 | B6: Přihlášení | C6: profikasa | D6: CZ60738677 | E6: 96 | F6: Pokladna SCO1 | H6: 0 | I6: =L6+M6+N6 -> 0 | J6: =O6+P6 -> 0 | K6: =IF(H6=I6+J6,0,W6) -> 0 | L6: 0 | M6: 0 | N6: 0 | O6: 0 | P6: 0 | Q6: 0 | R6: 0 | S6: 0 | T6: 0 | U6: 0 | V6: 0 | W6: 0 | Y6: 0 | Z6: 0 | AA6: 0 | AB6: 0 | AC6: 0 | AD6: 0 | AE6: 0 | AF6: 0 | AG6: 46132.015 | AH6: 0 | AI6: 0 | AJ6: =AH6+AI6 -> 0
A7: 46132.292 | B7: Převod | C7: převod z 19.04.2026 | E7: -1 | H7: 0 | I7: =L7+M7+N7 -> 0 | J7: =O7+P7 -> 0 | K7: =IF(H7=I7+J7,0,W7) -> 0 | L7: 0 | M7: 0 | N7: 0 | O7: 0 | P7: 0 | Q7: 0 | R7: 0 | S7: 0 | T7: 0 | U7: 0 | V7: 0 | W7: 0 | X7: 0 | Y7: 0 | Z7: 0 | AA7: 0 | AB7: 0 | AC7: 0 | AD7: 0 | AE7: 0 | AF7: 0 | AG7: 46132.292 | AH7: 26214 | AI7: 0 | AJ7: =AH7+AI7 -> 26214
A8: 46132.292 | B8: Přihlášení | C8: Teclová | D8: CZ60738677 | E8: 96 | F8: Pokladna 1 | H8: 0 | I8: =L8+M8+N8 -> 0 | J8: =O8+P8 -> 0 | K8: =IF(H8=I8+J8,0,W8) -> 0 | L8: 0 | M8: 0 | N8: 0 | O8: 0 | P8: 0 | Q8: 0 | R8: 0 | S8: 0 | T8: 0 | U8: 0 | V8: 0 | W8: 0 | Y8: 0 | Z8: 0 | AA8: 0 | AB8: 0 | AC8: 0 | AD8: 0 | AE8: 0 | AF8: 0 | AG8: 46132.292 | AH8: 26214 | AI8: 0 | AJ8: =AH8+AI8 -> 26214
A9: 46132.293 | B9: Prodej | C9: Teclová | D9: CZ60738677 | E9: 96 | F9: Pokladna 1 | G9: 166004504 | H9: 69.7 | I9: =L9+M9+N9 -> 59.848 | J9: =O9+P9 -> 9.852 | K9: =IF(H9=I9+J9,0,W9) -> 0 | L9: 29.6694 | M9: 30.1786 | N9: 0 | O9: 6.2306 | P9: 3.6214 | Q9: 59.848 | R9: 69.7 | S9: 0 | T9: 0 | U9: 0 | V9: 0 | W9: 0 | X9: 0 | Y9: 0 | Z9: 69.7 | AA9: 0 | AB9: 0 | AC9: 0 | AD9: 0 | AE9: 0 | AF9: 0 | AG9: 46132.293 | AH9: 26214 | AI9: 0 | AJ9: =AH9+AI9 -> 26214 | AK9: 0
A10: 46132.294 | B10: Prodej | C10: Teclová | D10: CZ60738677 | E10: 96 | F10: Pokladna 1 | G10: 166004505 | H10: 51.4 | I10: =L10+M10+N10 -> 42.4793 | J10: =O10+P10 -> 8.9207 | K10: =IF(H10=I10+J10,0,W10) -> 0 | L10: 42.4793 | M10: 0 | N10: 0 | O10: 8.9207 | P10: 0 | Q10: 42.4793 | R10: 51.4 | S10: 0 | T10: 0 | U10: 0 | V10: 0 | W10: 0 | X10: 0 | Y10: 0 | Z10: 51.4 | AA10: 0 | AB10: 0 | AC10: 0 | AD10: 0 | AE10: 0 | AF10: 0 | AG10: 46132.294 | AH10: 26214 | AI10: 0 | AJ10: =AH10+AI10 -> 26214 | AK10: 0
A11: 46132.295 | B11: Prodej | C11: Teclová | D11: CZ60738677 | E11: 96 | F11: Pokladna 1 | G11: 166004506 | H11: 38 | I11: =L11+M11+N11 -> 31.2396 | J11: =O11+P11 -> 6.5604 | K11: =IF(H11=I11+J11,0,W11) -> 0.2 | L11: 31.2396 | M11: 0 | N11: 0 | O11: 6.5604 | P11: 0 | Q11: 31.2396 | R11: 37.8 | S11: 0 | T11: 0 | U11: 0 | V11: 0 | W11: 0.2 | X11: 50 | Y11: 0 | Z11: 0 | AA11: 0 | AB11: 0 | AC11: 0 | AD11: 0 | AE11: 0 | AF11: 0 | AG11: 46132.295 | AH11: 26252 | AI11: 0 | AJ11: =AH11+AI11 -> 26252 | AK11: 0
A12: 46132.295 | B12: Prodej | C12: Teclová | D12: CZ60738677 | E12: 96 | F12: Pokladna 1 | G12: 166004507 | H12: 70 | I12: =L12+M12+N12 -> 62.8572 | J12: =O12+P12 -> 7.5428 | K12: =IF(H12=I12+J12,0,W12) -> -0.4 | L12: 0 | M12: 62.8572 | N12: 0 | O12: 0 | P12: 7.5428 | Q12: 62.8572 | R12: 70.4 | S12: 0 | T12: 0 | U12: 0 | V12: 0 | W12: -0.4 | X12: 100 | Y12: 0 | Z12: 0 | AA12: 0 | AB12: 0 | AC12: 0 | AD12: 0 | AE12: 0 | AF12: 0 | AG12: 46132.295 | AH12: 26322 | AI12: 0 | AJ12: =AH12+AI12 -> 26322 | AK12: 0
A13: 46132.297 | B13: Prodej | C13: Teclová | D13: CZ60738677 | E13: 96 | F13: Pokladna 1 | G13: 166004508 | H13: 253 | I13: =L13+M13+N13 -> 219.2109 | J13: =O13+P13 -> 33.6391 | K13: =IF(H13=I13+J13,0,W13) -> 0.15 | L13: 81.4875 | M13: 137.7234 | N13: 0 | O13: 17.1125 | P13: 16.5266 | Q13: 219.2109 | R13: 252.85 | S13: 0 | T13: 0 | U13: 0 | V13: 0 | W13: 0.15 | X13: 500 | Y13: 0 | Z13: 0 | AA13: 0 | AB13: 0 | AC13: 0 | AD13: 0 | AE13: 0 | AF13: 0 | AG13: 46132.297 | AH13: 26575 | AI13: 0 | AJ13: =AH13+AI13 -> 26575 | AK13: 0
A14: 46132.298 | B14: Prodej | C14: Teclová | D14: CZ60738677 | E14: 96 | F14: Pokladna 1 | G14: 166004509 | H14: 32 | I14: =L14+M14+N14 -> 26.281 | J14: =O14+P14 -> 5.519 | K14: =IF(H14=I14+J14,0,W14) -> 0.2 | L14: 26.281 | M14: 0 | N14: 0 | O14: 5.519 | P14: 0 | Q14: 26.281 | R14: 31.8 | S14: 0 | T14: 0 | U14: 0 | V14: 0 | W14: 0.2 | X14: 32 | Y14: 0 | Z14: 0 | AA14: 0 | AB14: 0 | AC14: 0 | AD14: 0 | AE14: 0 | AF14: 0 | AG14: 46132.298 | AH14: 26607 | AI14: 0 | AJ14: =AH14+AI14 -> 26607 | AK14: 0
A15: 46132.299 | B15: Prodej | C15: Teclová | D15: CZ60738677 | E15: 96 | F15: Pokladna 1 | G15: 166004510 | H15: 164 | I15: =L15+M15+N15 -> 141.3984 | J15: =O15+P15 -> 22.5316 | K15: =IF(H15=I15+J15,0,W15) -> 0.07 | L15: 61.8182 | M15: 79.5802 | N15: 0 | O15: 12.9818 | P15: 9.5498 | Q15: 141.3984 | R15: 163.93 | S15: 0 | T15: 0 | U15: 0 | V15: 0 | W15: 0.07 | X15: 500 | Y15: 0 | Z15: 0 | AA15: 0 | AB15: 0 | AC15: 0 | AD15: 0 | AE15: 0 | AF15: 0 | AG15: 46132.299 | AH15: 26771 | AI15: 0 | AJ15: =AH15+AI15 -> 26771 | AK15: 0
A16: 46132.3 | B16: Prodej | C16: Teclová | D16: CZ60738677 | E16: 96 | F16: Pokladna 1 | G16: 166004511 | H16: 198.41 | I16: =L16+M16+N16 -> 175.8304 | J16: =O16+P16 -> 22.5796 | K16: =IF(H16=I16+J16,0,W16) -> 0 | L16: 16.4463 | M16: 159.3841 | N16: 0 | O16: 3.4537 | P16: 19.1259 | Q16: 175.8304 | R16: 198.41 | S16: 0 | T16: 0 | U16: 0 | V16: 0 | W16: 0 | X16: 0 | Y16: 0 | Z16: 198.41 | AA16: 0 | AB16: 0 | AC16: 0 | AD16: 0 | AE16: 0 | AF16: 0 | AG16: 46132.3 | AH16: 26771 | AI16: 0 | AJ16: =AH16+AI16 -> 26771 | AK16: 0
A17: 46132.302 | B17: Prodej | C17: Teclová | D17: CZ60738677 | E17: 96 | F17: Pokladna 1 | G17: 166004512 | H17: 200 | I17: =L17+M17+N17 -> 165.2893 | J17: =O17+P17 -> 34.7107 | K17: =IF(H17=I17+J17,0,W17) -> 0 | L17: 165.2893 | M17: 0 | N17: 0 | O17: 34.7107 | P17: 0 | Q17: 165.2893 | R17: 200 | S17: 0 | T17: 0 | U17: 0 | V17: 0 | W17: 0 | X17: 200 | Y17: 0 | Z17: 0 | AA17: 0 | AB17: 0 | AC17: 0 | AD17: 0 | AE17: 0 | AF17: 0 | AG17: 46132.302 | AH17: 26971 | AI17: 0 | AJ17: =AH17+AI17 -> 26971 | AK17: 0
A18: 46132.304 | B18: Prodej | C18: Teclová | D18: CZ60738677 | E18: 96 | F18: Pokladna 1 | G18: 166004513 | H18: 67.42 | I18: =L18+M18+N18 -> 60.1964 | J18: =O18+P18 -> 7.2236 | K18: =IF(H18=I18+J18,0,W18) -> 0 | L18: 0 | M18: 60.1964 | N18: 0 | O18: 0 | P18: 7.2236 | Q18: 60.1964 | R18: 67.42 | S18: 0 | T18: 0 | U18: 0 | V18: 0 | W18: 0 | X18: 0 | Y18: 0 | Z18: 67.42 | AA18: 0 | AB18: 0 | AC18: 0 | AD18: 0 | AE18: 0 | AF18: 0 | AG18: 46132.304 | AH18: 26971 | AI18: 0 | AJ18: =AH18+AI18 -> 26971 | AK18: 0
A19: 46132.304 | B19: Prodej | C19: Teclová | D19: CZ60738677 | E19: 96 | F19: Pokladna 1 | G19: 166004514 | H19: 104 | I19: =L19+M19+N19 -> 88.1936 | J19: =O19+P19 -> 16.2064 | K19: =IF(H19=I19+J19,0,W19) -> -0.4 | L19: 62.4794 | M19: 25.7142 | N19: 0 | O19: 13.1206 | P19: 3.0858 | Q19: 88.1936 | R19: 104.4 | S19: 0 | T19: 0 | U19: 0 | V19: 0 | W19: -0.4 | X19: 150 | Y19: 0 | Z19: 0 | AA19: 0 | AB19: 0 | AC19: 0 | AD19: 0 | AE19: 0 | AF19: 0 | AG19: 46132.304 | AH19: 27075 | AI19: 0 | AJ19: =AH19+AI19 -> 27075 | AK19: 0
A20: 46132.307 | B20: Prodej | C20: Teclová | D20: CZ60738677 | E20: 96 | F20: Pokladna 1 | G20: 166004515 | H20: 209.2 | I20: =L20+M20+N20 -> 186.7857 | J20: =O20+P20 -> 22.4143 | K20: =IF(H20=I20+J20,0,W20) -> 0 | L20: 0 | M20: 186.7857 | N20: 0 | O20: 0 | P20: 22.4143 | Q20: 186.7857 | R20: 209.2 | S20: 0 | T20: 0 | U20: 0 | V20: 0 | W20: 0 | X20: 0 | Y20: 0 | Z20: 209.2 | AA20: 0 | AB20: 0 | AC20: 0 | AD20: 0 | AE20: 0 | AF20: 0 | AG20: 46132.307 | AH20: 27075 | AI20: 0 | AJ20: =AH20+AI20 -> 27075 | AK20: 0
... A187: 46132.464 | B187: Prodej | C187: Teclová | D187: CZ60738677 | E187: 96 | F187: Pokladna 1 | G187: 166004664 | H187: 222 | I187: =L187+M187+N187 -> 195.484 | J187: =O187+P187 -> 27.006 | K187: =IF(H187=I187+J187,0,W187) -> -0.49 | L187: 39.4215 | M187: 156.0625 | N187: 0 | O187: 8.2785 | P187: 18.7275 | Q187: 195.484 | R187: 222.49 | S187: 0 | T187: 0 | U187: 0 | V187: 0 | W187: -0.49 | X187: 502 | Y187: 0 | Z187: 0 | AA187: 0 | AB187: 0 | AC187: 0 | AD187: 0 | AE187: 0 | AF187: 0 | AG187: 46132.464 | AH187: 38130 | AI187: 0 | AJ187: =AH187+AI187 -> 38130 | AK187: 0
A188: 46132.465 | B188: Převod | C188: převod z 19.04.2026 | E188: -1 | H188: 0 | I188: =L188+M188+N188 -> 0 | J188: =O188+P188 -> 0 | K188: =IF(H188=I188+J188,0,W188) -> 0 | L188: 0 | M188: 0 | N188: 0 | O188: 0 | P188: 0 | Q188: 0 | R188: 0 | S188: 0 | T188: 0 | U188: 0 | V188: 0 | W188: 0 | X188: 0 | Y188: 0 | Z188: 0 | AA188: 0 | AB188: 0 | AC188: 0 | AD188: 0 | AE188: 0 | AF188: 0 | AG188: 46132.465 | AH188: 23360 | AI188: 0 | AJ188: =AH188+AI188 -> 23360
A189: 46132.465 | B189: Přihlášení | C189: profikasa | D189: CZ60738677 | E189: 96 | F189: Pokladna 2 | H189: 0 | I189: =L189+M189+N189 -> 0 | J189: =O189+P189 -> 0 | K189: =IF(H189=I189+J189,0,W189) -> 0 | L189: 0 | M189: 0 | N189: 0 | O189: 0 | P189: 0 | Q189: 0 | R189: 0 | S189: 0 | T189: 0 | U189: 0 | V189: 0 | W189: 0 | Y189: 0 | Z189: 0 | AA189: 0 | AB189: 0 | AC189: 0 | AD189: 0 | AE189: 0 | AF189: 0 | AG189: 46132.465 | AH189: 23360 | AI189: 0 | AJ189: =AH189+AI189 -> 23360
A190: 46132.466 | B190: Odhášení | C190: profikasa | D190: CZ60738677 | E190: 96 | F190: Pokladna 2 | H190: 0 | I190: =L190+M190+N190 -> 0 | J190: =O190+P190 -> 0 | K190: =IF(H190=I190+J190,0,W190) -> 0 | L190: 0 | M190: 0 | N190: 0 | O190: 0 | P190: 0 | Q190: 0 | R190: 0 | S190: 0 | T190: 0 | U190: 0 | V190: 0 | W190: 0 | Y190: 0 | Z190: 0 | AA190: 0 | AB190: 0 | AC190: 0 | AD190: 0 | AE190: 0 | AF190: 0 | AG190: 46132.466 | AH190: 23360 | AI190: 0 | AJ190: =AH190+AI190 -> 23360
A191: 46132.466 | B191: Přihlášení | C191: profikasa | D191: CZ60738677 | E191: 96 | F191: Pokladna 1 | H191: 0 | I191: =L191+M191+N191 -> 0 | J191: =O191+P191 -> 0 | K191: =IF(H191=I191+J191,0,W191) -> 0 | L191: 0 | M191: 0 | N191: 0 | O191: 0 | P191: 0 | Q191: 0 | R191: 0 | S191: 0 | T191: 0 | U191: 0 | V191: 0 | W191: 0 | Y191: 0 | Z191: 0 | AA191: 0 | AB191: 0 | AC191: 0 | AD191: 0 | AE191: 0 | AF191: 0 | AG191: 46132.466 | AH191: 38130 | AI191: 0 | AJ191: =AH191+AI191 -> 38130
A192: 46132.466 | B192: Odhášení | C192: profikasa | D192: CZ60738677 | E192: 96 | F192: Pokladna 1 | H192: 0 | I192: =L192+M192+N192 -> 0 | J192: =O192+P192 -> 0 | K192: =IF(H192=I192+J192,0,W192) -> 0 | L192: 0 | M192: 0 | N192: 0 | O192: 0 | P192: 0 | Q192: 0 | R192: 0 | S192: 0 | T192: 0 | U192: 0 | V192: 0 | W192: 0 | Y192: 0 | Z192: 0 | AA192: 0 | AB192: 0 | AC192: 0 | AD192: 0 | AE192: 0 | AF192: 0 | AG192: 46132.466 | AH192: 38130 | AI192: 0 | AJ192: =AH192+AI192 -> 38130
A193: 46132.466 | B193: Přihlášení | C193: Teclová | D193: CZ60738677 | E193: 96 | F193: Pokladna 1 | H193: 0 | I193: =L193+M193+N193 -> 0 | J193: =O193+P193 -> 0 | K193: =IF(H193=I193+J193,0,W193) -> 0 | L193: 0 | M193: 0 | N193: 0 | O193: 0 | P193: 0 | Q193: 0 | R193: 0 | S193: 0 | T193: 0 | U193: 0 | V193: 0 | W193: 0 | Y193: 0 | Z193: 0 | AA193: 0 | AB193: 0 | AC193: 0 | AD193: 0 | AE193: 0 | AF193: 0 | AG193: 46132.466 | AH193: 38130 | AI193: 0 | AJ193: =AH193+AI193 -> 38130
A194: 46132.467 | B194: Prodej | C194: Teclová | D194: CZ60738677 | E194: 96 | F194: Pokladna 1 | G194: 166004665 | H194: 51 | I194: =L194+M194+N194 -> 45.3392 | J194: =O194+P194 -> 5.4408 | K194: =IF(H194=I194+J194,0,W194) -> 0.22 | L194: 0 | M194: 45.3392 | N194: 0 | O194: 0 | P194: 5.4408 | Q194: 45.3392 | R194: 50.78 | S194: 0 | T194: 0 | U194: 0 | V194: 0 | W194: 0.22 | X194: 51 | Y194: 0 | Z194: 0 | AA194: 0 | AB194: 0 | AC194: 0 | AD194: 0 | AE194: 0 | AF194: 0 | AG194: 46132.467 | AH194: 38181 | AI194: 0 | AJ194: =AH194+AI194 -> 38181 | AK194: 0
A195: 46132.468 | B195: Prodej | C195: Teclová | D195: CZ60738677 | E195: 96 | F195: Pokladna 1 | G195: 166004666 | H195: 50 | I195: =L195+M195+N195 -> 41.2397 | J195: =O195+P195 -> 8.6603 | K195: =IF(H195=I195+J195,0,W195) -> 0.1 | L195: 41.2397 | M195: 0 | N195: 0 | O195: 8.6603 | P195: 0 | Q195: 41.2397 | R195: 49.9 | S195: 0 | T195: 0 | U195: 0 | V195: 0 | W195: 0.1 | X195: 50 | Y195: 0 | Z195: 0 | AA195: 0 | AB195: 0 | AC195: 0 | AD195: 0 | AE195: 0 | AF195: 0 | AG195: 46132.468 | AH195: 38231 | AI195: 0 | AJ195: =AH195+AI195 -> 38231 | AK195: 0
A196: 46132.469 | B196: Prodej | C196: Teclová | D196: CZ60738677 | E196: 96 | F196: Pokladna 1 | G196: 166004667 | H196: 653 | I196: =L196+M196+N196 -> 561.4099 | J196: =O196+P196 -> 91.8401 | K196: =IF(H196=I196+J196,0,W196) -> -0.25 | L196: 271.9008 | M196: 289.5091 | N196: 0 | O196: 57.0992 | P196: 34.7409 | Q196: 561.4099 | R196: 653.25 | S196: 0 | T196: 0 | U196: 0 | V196: 0 | W196: -0.25 | X196: 1000 | Y196: 0 | Z196: 0 | AA196: 0 | AB196: 0 | AC196: 0 | AD196: 0 | AE196: 0 | AF196: 0 | AG196: 46132.469 | AH196: 38884 | AI196: 0 | AJ196: =AH196+AI196 -> 38884 | AK196: 10.4805
A197: 46132.469 | B197: Prodej | C197: Teclová | D197: CZ60738677 | E197: 96 | F197: Pokladna 1 | G197: 166004668 | H197: 15 | I197: =L197+M197+N197 -> 12.314 | J197: =O197+P197 -> 2.586 | K197: =IF(H197=I197+J197,0,W197) -> 0.1 | L197: 12.314 | M197: 0 | N197: 0 | O197: 2.586 | P197: 0 | Q197: 12.314 | R197: 14.9 | S197: 0 | T197: 0 | U197: 0 | V197: 0 | W197: 0.1 | X197: 20 | Y197: 0 | Z197: 0 | AA197: 0 | AB197: 0 | AC197: 0 | AD197: 0 | AE197: 0 | AF197: 0 | AG197: 46132.469 | AH197: 38899 | AI197: 0 | AJ197: =AH197+AI197 -> 38899 | AK197: 0
A198: 46132.47 | B198: Prodej | C198: Teclová | D198: CZ60738677 | E198: 96 | F198: Pokladna 1 | G198: 166004669 | H198: 148.6 | I198: =L198+M198+N198 -> 131.0249 | J198: =O198+P198 -> 17.5751 | K198: =IF(H198=I198+J198,0,W198) -> 0 | L198: 20.5785 | M198: 110.4464 | N198: 0 | O198: 4.3215 | P198: 13.2536 | Q198: 131.0249 | R198: 148.6 | S198: 0 | T198: 0 | U198: 0 | V198: 0 | W198: 0 | X198: 0 | Y198: 0 | Z198: 148.6 | AA198: 0 | AB198: 0 | AC198: 0 | AD198: 0 | AE198: 0 | AF198: 0 | AG198: 46132.47 | AH198: 38899 | AI198: 0 | AJ198: =AH198+AI198 -> 38899 | AK198: 0
A199: 46132.47 | B199: Prodej | C199: Teclová | D199: CZ60738677 | E199: 96 | F199: Pokladna 1 | G199: 166004670 | H199: 481 | I199: =L199+M199+N199 -> 415.4146 | J199: =O199+P199 -> 65.6854 | K199: =IF(H199=I199+J199,0,W199) -> -0.1 | L199: 175.9504 | M199: 239.4642 | N199: 0 | O199: 36.9496 | P199: 28.7358 | Q199: 415.4146 | R199: 481.1 | S199: 0 | T199: 0 | U199: 0 | V199: 0 | W199: -0.1 | X199: 2000 | Y199: 0 | Z199: 0 | AA199: 0 | AB199: 0 | AC199: 0 | AD199: 0 | AE199: 0 | AF199: 0 | AG199: 46132.47 | AH199: 39380 | AI199: 0 | AJ199: =AH199+AI199 -> 39380 | AK199: 0
A200: 46132.471 | B200: Prodej | C200: Teclová | D200: CZ60738677 | E200: 96 | F200: Pokladna 1 | G200: 166004671 | H200: 94 | I200: =L200+M200+N200 -> 83.5714 | J200: =O200+P200 -> 10.0286 | K200: =IF(H200=I200+J200,0,W200) -> 0.4 | L200: 0 | M200: 83.5714 | N200: 0 | O200: 0 | P200: 10.0286 | Q200: 83.5714 | R200: 93.6 | S200: 0 | T200: 0 | U200: 0 | V200: 0 | W200: 0.4 | X200: 94 | Y200: 0 | Z200: 0 | AA200: 0 | AB200: 0 | AC200: 0 | AD200: 0 | AE200: 0 | AF200: 0 | AG200: 46132.471 | AH200: 39474 | AI200: 0 | AJ200: =AH200+AI200 -> 39474 | AK200: 0
A201: 46132.471 | B201: Prodej | C201: Teclová | D201: CZ60738677 | E201: 96 | F201: Pokladna 1 | G201: 166004672 | H201: 123 | I201: =L201+M201+N201 -> 109.5536 | J201: =O201+P201 -> 13.1464 | K201: =IF(H201=I201+J201,0,W201) -> 0.3 | L201: 0 | M201: 109.5536 | N201: 0 | O201: 0 | P201: 13.1464 | Q201: 109.5536 | R201: 122.7 | S201: 0 | T201: 0 | U201: 0 | V201: 0 | W201: 0.3 | X201: 200 | Y201: 0 | Z201: 0 | AA201: 0 | AB201: 0 | AC201: 0 | AD201: 0 | AE201: 0 | AF201: 0 | AG201: 46132.471 | AH201: 39597 | AI201: 0 | AJ201: =AH201+AI201 -> 39597 | AK201: 0
A202: 46132.471 | B202: Prodej | C202: Teclová | D202: CZ60738677 | E202: 96 | F202: Pokladna 1 | G202: 166004673 | H202: 30 | I202: =L202+M202+N202 -> 26.9274 | J202: =O202+P202 -> 3.3726 | K202: =IF(H202=I202+J202,0,W202) -> -0.3 | L202: 1.5702 | M202: 25.3572 | N202: 0 | O202: 0.3298 | P202: 3.0428 | Q202: 26.9274 | R202: 30.3 | S202: 0 | T202: 0 | U202: 0 | V202: 0 | W202: -0.3 | X202: 30 | Y202: 0 | Z202: 0 | AA202: 0 | AB202: 0 | AC202: 0 | AD202: 0 | AE202: 0 | AF202: 0 | AG202: 46132.471 | AH202: 39627 | AI202: 0 | AJ202: =AH202+AI202 -> 39627 | AK202: 0
A203: 46132.472 | B203: Prodej | C203: Teclová | D203: CZ60738677 | E203: 96 | F203: Pokladna 1 | G203: 166004674 | H203: 5.77 | I203: =L203+M203+N203 -> 5.1518 | J203: =O203+P203 -> 0.6182 | K203: =IF(H203=I203+J203,0,W203) -> 0 | L203: 0 | M203: 5.1518 | N203: 0 | O203: 0 | P203: 0.6182 | Q203: 5.1518 | R203: 5.77 | S203: 0 | T203: 0 | U203: 0 | V203: 0 | W203: 0 | X203: 0 | Y203: 0 | Z203: 5.77 | AA203: 0 | AB203: 0 | AC203: 0 | AD203: 0 | AE203: 0 | AF203: 0 | AG203: 46132.472 | AH203: 39627 | AI203: 0 | AJ203: =AH203+AI203 -> 39627 | AK203: 0
A204: 46132.472 | B204: Prodej | C204: Teclová | D204: CZ60738677 | E204: 96 | F204: Pokladna 1 | G204: 166004675 | H204: 15.9 | I204: =L204+M204+N204 -> 14.1964 | J204: =O204+P204 -> 1.7036 | K204: =IF(H204=I204+J204,0,W204) -> 0 | L204: 0 | M204: 14.1964 | N204: 0 | O204: 0 | P204: 1.7036 | Q204: 14.1964 | R204: 15.9 | S204: 0 | T204: 0 | U204: 0 | V204: 0 | W204: 0 | X204: 0 | Y204: 0 | Z204: 15.9 | AA204: 0 | AB204: 0 | AC204: 0 | AD204: 0 | AE204: 0 | AF204: 0 | AG204: 46132.472 | AH204: 39627 | AI204: 0 | AJ204: =AH204+AI204 -> 39627 | AK204: 0
A205: 46132.474 | B205: Prodej | C205: Teclová | D205: CZ60738677 | E205: 96 | F205: Pokladna 1 | G205: 166004676 | H205: 137 | I205: =L205+M205+N205 -> 117.6446 | J205: =O205+P205 -> 19.7554 | K205: =IF(H205=I205+J205,0,W205) -> -0.4 | L205: 62.6446 | M205: 55 | N205: 0 | O205: 13.1554 | P205: 6.6 | Q205: 117.6446 | R205: 137.4 | S205: 0 | T205: 0 | U205: 0 | V205: 0 | W205: -0.4 | X205: 237 | Y205: 0 | Z205: 0 | AA205: 0 | AB205: 0 | AC205: 0 | AD205: 0 | AE205: 0 | AF205: 0 | AG205: 46132.474 | AH205: 39764 | AI205: 0 | AJ205: =AH205+AI205 -> 39764 | AK205: 0
... A231: 46132.498 | B231: Prodej | C231: Teclová | D231: CZ60738677 | E231: 96 | F231: Pokladna 1 | G231: 166004701 | H231: 19.9 | I231: =L231+M231+N231 -> 17.7679 | J231: =O231+P231 -> 2.1321 | K231: =IF(H231=I231+J231,0,W231) -> 0 | L231: 0 | M231: 17.7679 | N231: 0 | O231: 0 | P231: 2.1321 | Q231: 17.7679 | R231: 19.9 | S231: 0 | T231: 0 | U231: 0 | V231: 0 | W231: 0 | X231: 0 | Y231: 0 | Z231: 19.9 | AA231: 0 | AB231: 0 | AC231: 0 | AD231: 0 | AE231: 0 | AF231: 0 | AG231: 46132.498 | AH231: 41177 | AI231: 0 | AJ231: =AH231+AI231 -> 41177 | AK231: 0
...

Sheet Fiskalizované doklady
A1: Identifikace | G1: Datum a doklad | J1: Tržba | N1: Dle sazeb DPH | S1: Dle věcného rozlišení | Z1: Platby | AF1: Hlášení EET | AL1: Poskytnuté slevy
J2: =SUBTOTAL(109,J4:J999880) -> 0 | K2: =SUBTOTAL(109,K4:K999880) -> 0 | L2: =SUBTOTAL(109,L4:L999880) -> 0 | M2: =SUBTOTAL(109,M4:M999880) -> 0 | N2: =SUBTOTAL(109,N4:N999880) -> 0 | O2: =SUBTOTAL(109,O4:O999880) -> 0 | P2: =SUBTOTAL(109,P4:P999880) -> 0 | Q2: =SUBTOTAL(109,Q4:Q999880) -> 0 | ... AB2: =SUBTOTAL(109,AB4:AB999880) -> 0 | AD2: =SUBTOTAL(109,AD4:AD999880) -> 0 | AE2: =SUBTOTAL(109,AE4:AE999880) -> 0 | AL2: =SUBTOTAL(109,AL4:AL999853) -> 0
A3: DIČ | B3: Název firmy | C3: ID provozovny | D3: Název provozovny | E3: ID pokladny | F3: Uživatel | G3: Datum | H3: Čas | I3: Číslo dokladu | J3: Tržba celkem | K3: Základ DPH celkem | L3: DPH Celkem | M3: Zaokrouhlení | N3: Základ DPH 21% | O3: Základ DPH 12% | P3: Základ DPH 0% | Q3: DPH 21% | R3: DPH 12% | S3: Prodané zboží bez DPH | T3: Prodané zboží s DPH | U3: Vrácené zboží bez DPH | V3: Vrácené zboží s DPH | W3: Prodané obaly | X3: Vykoupené obaly | Y3: Zaokrouhlení | Z3: Hotovost | AA3: Stravenky | AB3: Platební karta | AC3: Gastro konto | AD3: Cashback | AE3: Vráceno | AF3: Hlášení odesláno | AG3: Hlášení přijato | AH3: BKP | AI3: FIK | AJ3: PKP | AK3: UUID | AL3: Sleva na pokladně

Sheet Nefiskalizované doklady
A1: Identifikace | G1: Datum a doklad | J1: Tržba | N1: Dle sazeb DPH | S1: Dle věcného rozlišení | Z1: Platby | AF1: Poskytnuté slevy
J2: =SUBTOTAL(109,J4:J999948) -> 92316.38 | K2: =SUBTOTAL(109,K4:K999948) -> 79957.291 | L2: =SUBTOTAL(109,L4:L999948) -> 11784.839 | M2: =SUBTOTAL(109,M4:M999948) -> 21.23 | N2: =SUBTOTAL(109,N4:N999948) -> 24403.425 | O2: =SUBTOTAL(109,O4:O999948) -> 56035.246 | P2: =SUBTOTAL(109,P4:P999948) -> 6 | Q2: =SUBTOTAL(109,Q4:Q999948) -> 5125.0054 | ... AB2: =SUBTOTAL(109,AB4:AB999948) -> 53413.38 | AD2: =SUBTOTAL(109,AD4:AD999948) -> 0 | AE2: =SUBTOTAL(109,AE4:AE999948) -> -48314 | AF2: =SUBTOTAL(109,AF4:AF999853) -> 1083.0861
A3: DIČ | B3: Název firmy | C3: ID provozovny | D3: Název provozovny | E3: ID pokladny | F3: Uživatel | G3: Datum | H3: Čas | I3: Číslo dokladu | J3: Tržba celkem | K3: Základ DPH celkem | L3: DPH Celkem | M3: Zaokrouhlení | N3: Základ DPH 21% | O3: Základ DPH 12% | P3: Základ DPH 0% | Q3: DPH 21% | R3: DPH 12% | S3: Prodané zboží bez DPH | T3: Prodané zboží s DPH | U3: Vrácené zboží bez DPH | V3: Vrácené zboží s DPH | W3: Prodané obaly | X3: Vykoupené obaly | Y3: Zaokrouhlení | Z3: Hotovost | AA3: Stravenky | AB3: Platební karta | AC3: Gastro konto | AD3: Cashback | AE3: Vráceno | AF3: Sleva na pokladně
A4: CZ60738677 | B4: RAPO BRNO, s.r.o. | C4: 96 | D4: BALADA - Březinky | E4: Pokladna SCO2 | F4: profikasa | G4: 46132 | H4: 0.37474537 | I4: 163000332 | J4: 553.02 | K4: ==N4+O4+P4 -> FALSE | L4: ==Q4+R4 -> FALSE | M4: ==IF(J4=K4+L4,0,Y4) -> FALSE | N4: 78.84 | O4: 408.54 | P4: 0 | Q4: 16.56 | R4: 49.08 | S4: 487.38 | T4: 553.02 | U4: 0 | V4: 0 | W4: 0 | X4: 0 | Y4: 0 | Z4: 0 | AA4: 0 | AB4: 553.02 | AD4: 0 | AE4: 0 | AF4: 0
A5: CZ60738677 | B5: RAPO BRNO, s.r.o. | C5: 96 | D5: BALADA - Březinky | E5: Pokladna SCO2 | F5: profikasa | G5: 46132 | H5: 0.37981481 | I5: 163000333 | J5: 37.19 | K5: =N5+O5+P5 -> 33.2 | L5: =Q5+R5 -> 3.99 | M5: =IF(J5=K5+L5,0,Y5) -> 0 | N5: 0 | O5: 33.2 | P5: 0 | Q5: 0 | R5: 3.99 | S5: 33.2 | T5: 37.19 | U5: 0 | V5: 0 | W5: 0 | X5: 0 | Y5: 0 | Z5: 0 | AA5: 0 | AB5: 37.19 | AD5: 0 | AE5: 0 | AF5: 0
A6: CZ60738677 | B6: RAPO BRNO, s.r.o. | C6: 96 | D6: BALADA - Březinky | E6: Pokladna SCO2 | F6: profikasa | G6: 46132 | H6: 0.56572917 | I6: 163000334 | J6: 12.4 | K6: =N6+O6+P6 -> 11.07 | L6: =Q6+R6 -> 1.33 | M6: =IF(J6=K6+L6,0,Y6) -> 0 | N6: 0 | O6: 11.07 | P6: 0 | Q6: 0 | R6: 1.33 | S6: 11.07 | T6: 12.4 | U6: 0 | V6: 0 | W6: 0 | X6: 0 | Y6: 0 | Z6: 0 | AA6: 0 | AB6: 12.4 | AD6: 0 | AE6: 0 | AF6: 0
A7: CZ60738677 | B7: RAPO BRNO, s.r.o. | C7: 96 | D7: BALADA - Březinky | E7: Pokladna SCO2 | F7: profikasa | G7: 46132 | H7: 0.59159722 | I7: 163000335 | J7: 22.9 | K7: =N7+O7+P7 -> 20.44 | L7: =Q7+R7 -> 2.46 | M7: =IF(J7=K7+L7,0,Y7) -> 0 | N7: 0 | O7: 20.44 | P7: 0 | Q7: 0 | R7: 2.46 | S7: 20.44 | T7: 22.9 | U7: 0 | V7: 0 | W7: 0 | X7: 0 | Y7: 0 | Z7: 0 | AA7: 0 | AB7: 22.9 | AD7: 0 | AE7: 0 | AF7: 0
A8: CZ60738677 | B8: RAPO BRNO, s.r.o. | C8: 96 | D8: BALADA - Březinky | E8: Pokladna SCO2 | F8: profikasa | G8: 46132 | H8: 0.59576389 | I8: 163000336 | J8: 24.9 | K8: =N8+O8+P8 -> 22.23 | L8: =Q8+R8 -> 2.67 | M8: =IF(J8=K8+L8,0,Y8) -> 0 | N8: 0 | O8: 22.23 | P8: 0 | Q8: 0 | R8: 2.67 | S8: 22.23 | T8: 24.9 | U8: 0 | V8: 0 | W8: 0 | X8: 0 | Y8: 0 | Z8: 0 | AA8: 0 | AB8: 24.9 | AD8: 0 | AE8: 0 | AF8: 0
A9: CZ60738677 | B9: RAPO BRNO, s.r.o. | C9: 96 | D9: BALADA - Březinky | E9: Pokladna SCO2 | F9: profikasa | G9: 46132 | H9: 0.59795139 | I9: 163000337 | J9: 162 | K9: =N9+O9+P9 -> 133.88 | L9: =Q9+R9 -> 28.12 | M9: =IF(J9=K9+L9,0,Y9) -> 0 | N9: 133.88 | O9: 0 | P9: 0 | Q9: 28.12 | R9: 0 | S9: 133.88 | T9: 162 | U9: 0 | V9: 0 | W9: 0 | X9: 0 | Y9: 0 | Z9: 0 | AA9: 0 | AB9: 162 | AD9: 0 | AE9: 0 | AF9: 0
A10: CZ60738677 | B10: RAPO BRNO, s.r.o. | C10: 96 | D10: BALADA - Březinky | E10: Pokladna SCO2 | F10: profikasa | G10: 46132 | H10: 0.60578704 | I10: 163000338 | J10: 27.9 | K10: =N10+O10+P10 -> 23.05 | L10: =Q10+R10 -> 4.85 | M10: =IF(J10=K10+L10,0,Y10) -> 0 | N10: 23.05 | O10: 0 | P10: 0 | Q10: 4.85 | R10: 0 | S10: 23.05 | T10: 27.9 | U10: 0 | V10: 0 | W10: 0 | X10: 0 | Y10: 0 | Z10: 0 | AA10: 0 | AB10: 27.9 | AD10: 0 | AE10: 0 | AF10: 0
A11: CZ60738677 | B11: RAPO BRNO, s.r.o. | C11: 96 | D11: BALADA - Březinky | E11: Pokladna SCO2 | F11: profikasa | G11: 46132 | H11: 0.60625 | I11: 163000339 | J11: 29.3 | K11: =N11+O11+P11 -> 25.4 | L11: =Q11+R11 -> 3.9 | M11: =IF(J11=K11+L11,0,Y11) -> 0 | N11: 9.42 | O11: 15.98 | P11: 0 | Q11: 1.98 | R11: 1.92 | S11: 25.4 | T11: 29.3 | U11: 0 | V11: 0 | W11: 0 | X11: 0 | Y11: 0 | Z11: 0 | AA11: 0 | AB11: 29.3 | AD11: 0 | AE11: 0 | AF11: 0
A12: CZ60738677 | B12: RAPO BRNO, s.r.o. | C12: 96 | D12: BALADA - Březinky | E12: Pokladna SCO2 | F12: profikasa | G12: 46132 | H12: 0.60913194 | I12: 163000340 | J12: 34.9 | K12: =N12+O12+P12 -> 31.16 | L12: =Q12+R12 -> 3.74 | M12: =IF(J12=K12+L12,0,Y12) -> 0 | N12: 0 | O12: 31.16 | P12: 0 | Q12: 0 | R12: 3.74 | S12: 31.16 | T12: 34.9 | U12: 0 | V12: 0 | W12: 0 | X12: 0 | Y12: 0 | Z12: 0 | AA12: 0 | AB12: 34.9 | AD12: 0 | AE12: 0 | AF12: 0
A13: CZ60738677 | B13: RAPO BRNO, s.r.o. | C13: 96 | D13: BALADA - Březinky | E13: Pokladna SCO2 | F13: profikasa | G13: 46132 | H13: 0.60954861 | I13: 163000341 | J13: 95.8 | K13: =N13+O13+P13 -> 85.53 | L13: =Q13+R13 -> 10.27 | M13: =IF(J13=K13+L13,0,Y13) -> 0 | N13: 0 | O13: 85.53 | P13: 0 | Q13: 0 | R13: 10.27 | S13: 85.53 | T13: 95.8 | U13: 0 | V13: 0 | W13: 0 | X13: 0 | Y13: 0 | Z13: 0 | AA13: 0 | AB13: 95.8 | AD13: 0 | AE13: 0 | AF13: 0
A14: CZ60738677 | B14: RAPO BRNO, s.r.o. | C14: 96 | D14: BALADA - Březinky | E14: Pokladna SCO2 | F14: profikasa | G14: 46132 | H14: 0.61166667 | I14: 163000342 | J14: 54.8 | K14: =N14+O14+P14 -> 48.91 | L14: =Q14+R14 -> 5.89 | M14: =IF(J14=K14+L14,0,Y14) -> 0 | N14: 0 | O14: 48.91 | P14: 0 | Q14: 0 | R14: 5.89 | S14: 48.91 | T14: 54.8 | U14: 0 | V14: 0 | W14: 0 | X14: 0 | Y14: 0 | Z14: 0 | AA14: 0 | AB14: 54.8 | AD14: 0 | AE14: 0 | AF14: 0
A15: CZ60738677 | B15: RAPO BRNO, s.r.o. | C15: 96 | D15: BALADA - Březinky | E15: Pokladna SCO2 | F15: profikasa | G15: 46132 | H15: 0.62326389 | I15: 163000343 | J15: 93 | K15: =N15+O15+P15 -> 83.01 | L15: =Q15+R15 -> 9.99 | M15: =IF(J15=K15+L15,0,Y15) -> 0 | N15: 0 | O15: 83.01 | P15: 0 | Q15: 0 | R15: 9.99 | S15: 83.01 | T15: 93 | U15: 0 | V15: 0 | W15: 0 | X15: 0 | Y15: 0 | Z15: 0 | AA15: 0 | AB15: 93 | AD15: 0 | AE15: 0 | AF15: 0
A16: CZ60738677 | B16: RAPO BRNO, s.r.o. | C16: 96 | D16: BALADA - Březinky | E16: Pokladna SCO2 | F16: profikasa | G16: 46132 | H16: 0.62793981 | I16: 163000344 | J16: 31.8 | K16: =N16+O16+P16 -> 26.28 | L16: =Q16+R16 -> 5.52 | M16: =IF(J16=K16+L16,0,Y16) -> 0 | N16: 26.28 | O16: 0 | P16: 0 | Q16: 5.52 | R16: 0 | S16: 26.28 | T16: 31.8 | U16: 0 | V16: 0 | W16: 0 | X16: 0 | Y16: 0 | Z16: 0 | AA16: 0 | AB16: 31.8 | AD16: 0 | AE16: 0 | AF16: 0
... A28: CZ60738677 | B28: RAPO BRNO, s.r.o. | C28: 96 | D28: BALADA - Březinky | E28: Pokladna 1 | F28: Teclová | G28: 46132 | H28: 0.42050926 | I28: 166004612 | J28: 39 | K28: =N28+O28+P28 -> 34.625 | L28: =Q28+R28 -> 4.155 | M28: =IF(J28=K28+L28,0,Y28) -> 0.22 | N28: 0 | O28: 34.625 | P28: 0 | Q28: 0 | R28: 4.155 | S28: 34.625 | T28: 38.78 | U28: 0 | V28: 0 | W28: 0 | X28: 0 | Y28: 0.22 | Z28: 200 | AA28: 0 | AB28: 0 | AD28: 0 | AE28: -161 | AF28: 0
A29: CZ60738677 | B29: RAPO BRNO, s.r.o. | C29: 96 | D29: BALADA - Březinky | E29: Pokladna 1 | F29: Teclová | G29: 46132 | H29: 0.42090278 | I29: 166004613 | J29: 22.9 | K29: =N29+O29+P29 -> 18.9256 | L29: =Q29+R29 -> 3.9744 | M29: =IF(J29=K29+L29,0,Y29) -> 0 | N29: 18.9256 | O29: 0 | P29: 0 | Q29: 3.9744 | R29: 0 | S29: 18.9256 | T29: 22.9 | U29: 0 | V29: 0 | W29: 0 | X29: 0 | Y29: 0 | Z29: 0 | AA29: 0 | AB29: 22.9 | AC29: 0 | AD29: 0 | AE29: 0 | AF29: 0
A30: CZ60738677 | B30: RAPO BRNO, s.r.o. | C30: 96 | D30: BALADA - Březinky | E30: Pokladna 1 | F30: Teclová | G30: 46132 | H30: 0.42236111 | I30: 166004614 | J30: 39 | K30: =N30+O30+P30 -> 34.7232 | L30: =Q30+R30 -> 4.1668 | M30: =IF(J30=K30+L30,0,Y30) -> 0.11 | N30: 0 | O30: 34.7232 | P30: 0 | Q30: 0 | R30: 4.1668 | S30: 34.7232 | T30: 38.89 | U30: 0 | V30: 0 | W30: 0 | X30: 0 | Y30: 0.11 | Z30: 39 | AA30: 0 | AB30: 0 | AD30: 0 | AE30: 0 | AF30: 0
A31: CZ60738677 | B31: RAPO BRNO, s.r.o. | C31: 96 | D31: BALADA - Březinky | E31: Pokladna 1 | F31: Teclová | G31: 46132 | H31: 0.42359954 | I31: 166004615 | J31: 473.68 | K31: =N31+O31+P31 -> 422.9289 | L31: =Q31+R31 -> 50.7511 | M31: =IF(J31=K31+L31,0,Y31) -> 0 | N31: 0 | O31: 422.9289 | P31: 0 | Q31: 0 | R31: 50.7511 | S31: 422.9289 | T31: 473.68 | U31: 0 | V31: 0 | W31: 0 | X31: 0 | Y31: 0 | Z31: 0 | AA31: 0 | AB31: 473.68 | AC31: 0 | AD31: 0 | AE31: 0 | AF31: 0
A32: CZ60738677 | B32: RAPO BRNO, s.r.o. | C32: 96 | D32: BALADA - Březinky | E32: Pokladna 1 | F32: Teclová | G32: 46132 | H32: 0.42488426 | I32: 166004616 | J32: 121 | K32: =N32+O32+P32 -> 104.5868 | L32: =Q32+R32 -> 16.1132 | M32: =IF(J32=K32+L32,0,Y32) -> 0.3 | N32: 39.5868 | O32: 65 | P32: 0 | Q32: 8.3132 | R32: 7.8 | S32: 104.5868 | T32: 120.7 | U32: 0 | V32: 0 | W32: 0 | X32: 0 | Y32: 0.3 | Z32: 200 | AA32: 0 | AB32: 0 | AD32: 0 | AE32: -79 | AF32: 0
A33: CZ60738677 | B33: RAPO BRNO, s.r.o. | C33: 96 | D33: BALADA - Březinky | E33: Pokladna 1 | F33: Teclová | G33: 46132 | H33: 0.42532407 | I33: 166004617 | J33: 43 | K33: =N33+O33+P33 -> 38.3929 | L33: =Q33+R33 -> 4.6071 | M33: =IF(J33=K33+L33,0,Y33) -> 0 | N33: 0 | O33: 38.3929 | P33: 0 | Q33: 0 | R33: 4.6071 | S33: 38.3929 | T33: 43 | U33: 0 | V33: 0 | W33: 0 | X33: 0 | Y33: 0 | Z33: 0 | AA33: 0 | AB33: 43 | AC33: 0 | AD33: 0 | AE33: 0 | AF33: 0
A34: CZ60738677 | B34: RAPO BRNO, s.r.o. | C34: 96 | D34: BALADA - Březinky | E34: Pokladna 1 | F34: Teclová | G34: 46132 | H34: 0.42546296 | I34: 166004618 | J34: 48 | K34: =N34+O34+P34 -> 42.6786 | L34: =Q34+R34 -> 5.1214 | M34: =IF(J34=K34+L34,0,Y34) -> 0.2 | N34: 0 | O34: 42.6786 | P34: 0 | Q34: 0 | R34: 5.1214 | S34: 42.6786 | T34: 47.8 | U34: 0 | V34: 0 | W34: 0 | X34: 0 | Y34: 0.2 | Z34: 50 | AA34: 0 | AB34: 0 | AD34: 0 | AE34: -2 | AF34: 0
A35: CZ60738677 | B35: RAPO BRNO, s.r.o. | C35: 96 | D35: BALADA - Březinky | E35: Pokladna 1 | F35: Teclová | G35: 46132 | H35: 0.42611111 | I35: 166004619 | J35: 226.9 | K35: =N35+O35+P35 -> 202.5895 | L35: =Q35+R35 -> 24.3105 | M35: =IF(J35=K35+L35,0,Y35) -> 0 | N35: 0 | O35: 202.5895 | P35: 0 | Q35: 0 | R35: 24.3105 | S35: 202.5895 | T35: 226.9 | U35: 0 | V35: 0 | W35: 0 | X35: 0 | Y35: 0 | Z35: 0 | AA35: 0 | AB35: 226.9 | AC35: 0 | AD35: 0 | AE35: 0 | AF35: 0
A36: CZ60738677 | B36: RAPO BRNO, s.r.o. | C36: 96 | D36: BALADA - Březinky | E36: Pokladna 1 | F36: Teclová | G36: 46132 | H36: 0.4262037 | I36: 166004620 | J36: 68 | K36: =N36+O36+P36 -> 60.3482 | L36: =Q36+R36 -> 7.2418 | M36: =IF(J36=K36+L36,0,Y36) -> 0.41 | N36: 0 | O36: 60.3482 | P36: 0 | Q36: 0 | R36: 7.2418 | S36: 60.3482 | T36: 67.59 | U36: 0 | V36: 0 | W36: 0 | X36: 0 | Y36: 0.41 | Z36: 100 | AA36: 0 | AB36: 0 | AD36: 0 | AE36: -32 | AF36: 0
A37: CZ60738677 | B37: RAPO BRNO, s.r.o. | C37: 96 | D37: BALADA - Březinky | E37: Pokladna 1 | F37: Teclová | G37: 46132 | H37: 0.42648148 | I37: 166004621 | J37: 92 | K37: =N37+O37+P37 -> 79.1817 | L37: =Q37+R37 -> 12.6183 | M37: =IF(J37=K37+L37,0,Y37) -> 0.2 | N37: 34.6281 | O37: 44.5536 | P37: 0 | Q37: 7.2719 | R37: 5.3464 | S37: 79.1817 | T37: 91.8 | U37: 0 | V37: 0 | W37: 0 | X37: 0 | Y37: 0.2 | Z37: 102 | AA37: 0 | AB37: 0 | AD37: 0 | AE37: -10 | AF37: 0
A38: CZ60738677 | B38: RAPO BRNO, s.r.o. | C38: 96 | D38: BALADA - Březinky | E38: Pokladna 1 | F38: Teclová | G38: 46132 | H38: 0.43123843 | I38: 166004622 | J38: 53.8 | K38: =N38+O38+P38 -> 46.7142 | L38: =Q38+R38 -> 7.0858 | M38: =IF(J38=K38+L38,0,Y38) -> 0 | N38: 16.4463 | O38: 30.2679 | P38: 0 | Q38: 3.4537 | R38: 3.6321 | S38: 46.7142 | T38: 53.8 | U38: 0 | V38: 0 | W38: 0 | X38: 0 | Y38: 0 | Z38: 0 | AA38: 0 | AB38: 53.8 | AC38: 0 | AD38: 0 | AE38: 0 | AF38: 0
A39: CZ60738677 | B39: RAPO BRNO, s.r.o. | C39: 96 | D39: BALADA - Březinky | E39: Pokladna 1 | F39: Teclová | G39: 46132 | H39: 0.43149306 | I39: 166004623 | J39: 19.9 | K39: =N39+O39+P39 -> 16.4463 | L39: =Q39+R39 -> 3.4537 | M39: =IF(J39=K39+L39,0,Y39) -> 0 | N39: 16.4463 | O39: 0 | P39: 0 | Q39: 3.4537 | R39: 0 | S39: 16.4463 | T39: 19.9 | U39: 0 | V39: 0 | W39: 0 | X39: 0 | Y39: 0 | Z39: 0 | AA39: 0 | AB39: 19.9 | AC39: 0 | AD39: 0 | AE39: 0 | AF39: 0
A40: CZ60738677 | B40: RAPO BRNO, s.r.o. | C40: 96 | D40: BALADA - Březinky | E40: Pokladna 1 | F40: Teclová | G40: 46132 | H40: 0.4322338 | I40: 166004624 | J40: 88 | K40: =N40+O40+P40 -> 78.875 | L40: =Q40+R40 -> 9.465 | M40: =IF(J40=K40+L40,0,Y40) -> -0.34 | N40: 0 | O40: 78.875 | P40: 0 | Q40: 0 | R40: 9.465 | S40: 78.875 | T40: 88.34 | U40: 0 | V40: 0 | W40: 0 | X40: 0 | Y40: -0.34 | Z40: 200 | AA40: 0 | AB40: 0 | AD40: 0 | AE40: -112 | AF40: 0
A41: CZ60738677 | B41: RAPO BRNO, s.r.o. | C41: 96 | D41: BALADA - Březinky | E41: Pokladna 1 | F41: Teclová | G41: 46132 | H41: 0.43269676 | I41: 166004625 | J41: 75 | K41: =N41+O41+P41 -> 66.4318 | L41: =Q41+R41 -> 8.7082 | M41: =IF(J41=K41+L41,0,Y41) -> -0.14 | N41: 8.1818 | O41: 58.25 | P41: 0 | Q41: 1.7182 | R41: 6.99 | S41: 66.4318 | T41: 75.14 | U41: 0 | V41: 0 | W41: 0 | X41: 0 | Y41: -0.14 | Z41: 75 | AA41: 0 | AB41: 0 | AD41: 0 | AE41: 0 | AF41: 0
A42: CZ60738677 | B42: RAPO BRNO, s.r.o. | C42: 96 | D42: BALADA - Březinky | E42: Pokladna 1 | F42: Teclová | G42: 46132 | H42: 0.43283565 | I42: 166004626 | J42: 38 | K42: =N42+O42+P42 -> 33.8393 | L42: =Q42+R42 -> 4.0607 | M42: =IF(J42=K42+L42,0,Y42) -> 0.1 | N42: 0 | O42: 33.8393 | P42: 0 | Q42: 0 | R42: 4.0607 | S42: 33.8393 | T42: 37.9 | U42: 0 | V42: 0 | W42: 0 | X42: 0 | Y42: 0.1 | Z42: 50 | AA42: 0 | AB42: 0 | AD42: 0 | AE42: -12 | AF42: 0
A43: CZ60738677 | B43: RAPO BRNO, s.r.o. | C43: 96 | D43: BALADA - Březinky | E43: Pokladna 1 | F43: Teclová | G43: 46132 | H43: 0.43332176 | I43: 166004627 | J43: 254 | K43: =N43+O43+P43 -> 220.0454 | L43: =Q43+R43 -> 33.6646 | M43: =IF(J43=K43+L43,0,Y43) -> 0.29 | N43: 80.6613 | O43: 139.3841 | P43: 0 | Q43: 16.9387 | R43: 16.7259 | S43: 220.0454 | T43: 253.71 | U43: 0 | V43: 0 | W43: 0 | X43: 0 | Y43: 0.29 | Z43: 500 | AA43: 0 | AB43: 0 | AD43: 0 | AE43: -246 | AF43: 0
A44: CZ60738677 | B44: RAPO BRNO, s.r.o. | C44: 96 | D44: BALADA - Březinky | E44: Pokladna 1 | F44: Teclová | G44: 46132 | H44: 0.43450231 | I44: 166004628 | J44: 181 | K44: =N44+O44+P44 -> 161.9285 | L44: =Q44+R44 -> 19.4315 | M44: =IF(J44=K44+L44,0,Y44) -> -0.36 | N44: 0 | O44: 161.9285 | P44: 0 | Q44: 0 | R44: 19.4315 | S44: 161.9285 | T44: 181.36 | U44: 0 | V44: 0 | W44: 0 | X44: 0 | Y44: -0.36 | Z44: 200 | AA44: 0 | AB44: 0 | AD44: 0 | AE44: -19 | AF44: 0
A45: CZ60738677 | B45: RAPO BRNO, s.r.o. | C45: 96 | D45: BALADA - Březinky | E45: Pokladna 1 | F45: Teclová | G45: 46132 | H45: 0.43509259 | I45: 166004629 | J45: 222.3 | K45: =N45+O45+P45 -> 190.8516 | L45: =Q45+R45 -> 31.4484 | M45: =IF(J45=K45+L45,0,Y45) -> 0 | N45: 94.9587 | O45: 95.8929 | P45: 0 | Q45: 19.9413 | R45: 11.5071 | S45: 190.8516 | T45: 222.3 | U45: 0 | V45: 0 | W45: 0 | X45: 0 | Y45: 0 | Z45: 0 | AA45: 0 | AB45: 222.3 | AC45: 0 | AD45: 0 | AE45: 0 | AF45: 0
A46: CZ60738677 | B46: RAPO BRNO, s.r.o. | C46: 96 | D46: BALADA - Březinky | E46: Pokladna 1 | F46: Teclová | G46: 46132 | H46: 0.43631944 | I46: 166004630 | J46: 352.94 | K46: =N46+O46+P46 -> 315.1253 | L46: =Q46+R46 -> 37.8147 | M46: =IF(J46=K46+L46,0,Y46) -> 0 | N46: 0 | O46: 315.1253 | P46: 0 | Q46: 0 | R46: 37.8147 | S46: 315.1253 | T46: 352.94 | U46: 0 | V46: 0 | W46: 0 | X46: 0 | Y46: 0 | Z46: 0 | AA46: 0 | AB46: 352.94 | AC46: 0 | AD46: 0 | AE46: 0 | AF46: 0
A47: CZ60738677 | B47: RAPO BRNO, s.r.o. | C47: 96 | D47: BALADA - Březinky | E47: Pokladna 1 | F47: Teclová | G47: 46132 | H47: 0.43739583 | I47: 166004631 | J47: 255.55 | K47: =N47+O47+P47 -> 223.7338 | L47: =Q47+R47 -> 31.8162 | M47: =IF(J47=K47+L47,0,Y47) -> 0 | N47: 55.2066 | O47: 168.5272 | P47: 0 | Q47: 11.5934 | R47: 20.2228 | S47: 223.7338 | T47: 255.55 | U47: 0 | V47: 0 | W47: 0 | X47: 0 | Y47: 0 | Z47: 0 | AA47: 0 | AB47: 255.55 | AC47: 0 | AD47: 0 | AE47: 0 | AF47: 8.7431
A48: CZ60738677 | B48: RAPO BRNO, s.r.o. | C48: 96 | D48: BALADA - Březinky | E48: Pokladna 1 | F48: Teclová | G48: 46132 | H48: 0.43763889 | I48: 166004632 | J48: 21.9 | K48: =N48+O48+P48 -> 19.5536 | L48: =Q48+R48 -> 2.3464 | M48: =IF(J48=K48+L48,0,Y48) -> 0 | N48: 0 | O48: 19.5536 | P48: 0 | Q48: 0 | R48: 2.3464 | S48: 19.5536 | T48: 21.9 | U48: 0 | V48: 0 | W48: 0 | X48: 0 | Y48: 0 | Z48: 0 | AA48: 0 | AB48: 21.9 | AC48: 0 | AD48: 0 | AE48: 0 | AF48: 0
A49: CZ60738677 | B49: RAPO BRNO, s.r.o. | C49: 96 | D49: BALADA - Březinky | E49: Pokladna 1 | F49: Teclová | G49: 46132 | H49: 0.43792824 | I49: 166004633 | J49: 161 | K49: =N49+O49+P49 -> 133.0579 | L49: =Q49+R49 -> 27.9421 | M49: =IF(J49=K49+L49,0,Y49) -> 0 | N49: 133.0579 | O49: 0 | P49: 0 | Q49: 27.9421 | R49: 0 | S49: 133.0579 | T49: 161 | U49: 0 | V49: 0 | W49: 0 | X49: 0 | Y49: 0 | Z49: 0 | AA49: 0 | AB49: 161 | AC49: 0 | AD49: 0 | AE49: 0 | AF49: 0
A50: CZ60738677 | B50: RAPO BRNO, s.r.o. | C50: 96 | D50: BALADA - Březinky | E50: Pokladna 1 | F50: Teclová | G50: 46132 | H50: 0.43881944 | I50: 166004634 | J50: 421 | K50: =N50+O50+P50 -> 376.2768 | L50: =Q50+R50 -> 45.1532 | M50: =IF(J50=K50+L50,0,Y50) -> -0.43 | N50: 0 | O50: 376.2768 | P50: 0 | Q50: 0 | R50: 45.1532 | S50: 376.2768 | T50: 421.43 | U50: 0 | V50: 0 | W50: 0 | X50: 0 | Y50: -0.43 | Z50: 421 | AA50: 0 | AB50: 0 | AD50: 0 | AE50: 0 | AF50: 0
A51: CZ60738677 | B51: RAPO BRNO, s.r.o. | C51: 96 | D51: BALADA - Březinky | E51: Pokladna 1 | F51: Teclová | G51: 46132 | H51: 0.43925926 | I51: 166004635 | J51: 80.21 | K51: =N51+O51+P51 -> 71.6161 | L51: =Q51+R51 -> 8.5939 | M51: =IF(J51=K51+L51,0,Y51) -> 0 | N51: 0 | O51: 71.6161 | P51: 0 | Q51: 0 | R51: 8.5939 | S51: 71.6161 | T51: 80.21 | U51: 0 | V51: 0 | W51: 0 | X51: 0 | Y51: 0 | Z51: 0 | AA51: 0 | AB51: 80.21 | AC51: 0 | AD51: 0 | AE51: 0 | AF51: 13.974
...

Sheet Položky dokladů
A1: Identifikace | G1: Datum a doklad | K1: Zboží | P1: Akce | R1: Jednotková cena zboží a obalu | W1: Množství | Y1: Celkem za položku zboží a obalu | AD1: Sleva na pokladně
A2: DIČ | B2: Název firmy | C2: ID provozovny | D2: Název provozovny | E2: ID pokladny | F2: Uživatel | G2: Datum | H2: Čas | I2: Číslo dokladu | J2: Fiskalizace | K2: Číslo zboží | L2: EAN kód | M2: Výrobce | N2: Třídící strom | O2: Název zboží | P2: Příznak akce | Q2: Kód akce | R2: Zboží | V2: Obal | W2: Množství | X2: Jednotka | Y2: =SUBTOTAL(109,Y4:Y999225) -> 92256.226 | Z2: =SUBTOTAL(109,Z4:Z999225) -> 80410.622 | AA2: =SUBTOTAL(109,AA4:AA999225) -> 11845.604 | AB2: =SUBTOTAL(109,AB4:AB999225) -> 6 | AC2: =SUBTOTAL(109,AC4:AC999225) -> 92295.126 | AD2: =SUBTOTAL(109,AD4:AD999225) -> 117438.25 | AE2: =SUBTOTAL(109,AE4:AE999225) -> 3356.43 | AF2: =SUBTOTAL(109,AF4:AF999225) -> 1083.0861
R3: Cena s DPH | S3: Základ DPH | T3: DPH | U3: Sazba DPH | V3: Cena | Y3: Celkem zboží s DPH | Z3: Celkem zboží základ DPH | AA3: Celkem zboží DPH | AB3: Celkem obaly | AC3: Celkem zboží a obaly s DPH | AD3: Původní jednotková Cena s DPH | AE3: Jednotková Sleva | AF3: Sleva celkem za položku zboží
A4: CZ60738677 | B4: RAPO BRNO, s.r.o. | C4: 96 | D4: BALADA - Březinky | E4: Pokladna SCO1 | F4: profikasa | G4: 46132 | H4: 0.3162963 | I4: 161000330 | J4: NE | K4: 13336602 | L4: 8595019696884 | M4: CARLA spol. s r.o. | N4: 51102 | O4: Laguna Mořské plody mléčná | P4: NE | R4: 32.9 | S4: ==R4-T4 -> FALSE | T4: ==R4*U4/(U4+100) -> FALSE | U4: 12 | V4: 0 | W4: 1 | X4: KS | Y4: ==R4*W4 -> FALSE | Z4: ==S4*W4 -> FALSE | AA4: ==T4*W4 -> FALSE | AB4: ==V4*W4 -> FALSE | AC4: =(R4+V4)*W4 -> 32.9 | AD4: 32.9 | AE4: 0 | AF4: 0
A5: CZ60738677 | B5: RAPO BRNO, s.r.o. | C5: 96 | D5: BALADA - Březinky | E5: Pokladna SCO1 | F5: profikasa | G5: 46132 | H5: 0.31802083 | I5: 161000331 | J5: NE | K5: 48119602 | L5: 8594057637859 | M5: MASPEX CZECH, s.r.o. | N5: 52209 | O5: Tiger energy drink 1l | P5: NE | R5: 23.9 | S5: =R5-T5 -> 19.752066 | T5: =R5*U5/(U5+100) -> 4.1479339 | U5: 21 | V5: 0 | W5: 1 | X5: KS | Y5: =R5*W5 -> 23.9 | Z5: =S5*W5 -> 19.752066 | AA5: =T5*W5 -> 4.1479339 | AB5: =V5*W5 -> 0 | AC5: =(R5+V5)*W5 -> 23.9 | AD5: 23.9 | AE5: 0 | AF5: 0
A6: CZ60738677 | B6: RAPO BRNO, s.r.o. | C6: 96 | D6: BALADA - Březinky | E6: Pokladna SCO1 | F6: profikasa | G6: 46132 | H6: 0.3306713 | I6: 161000332 | J6: NE | K6: 21153380 | L6: 5900749624961 | M6: FS IMPORT- EXPORT s.r.o. | N6: 50201 | O6: BA! Energy Bar 5 forest fr | P6: NE | R6: 10.9 | S6: =R6-T6 -> 9.7321429 | T6: =R6*U6/(U6+100) -> 1.1678571 | U6: 12 | V6: 0 | W6: 1 | X6: KS | Y6: =R6*W6 -> 10.9 | Z6: =S6*W6 -> 9.7321429 | AA6: =T6*W6 -> 1.1678571 | AB6: =V6*W6 -> 0 | AC6: =(R6+V6)*W6 -> 10.9 | AD6: 10.9 | AE6: 0 | AF6: 0
A7: CZ60738677 | B7: RAPO BRNO, s.r.o. | C7: 96 | D7: BALADA - Březinky | E7: Pokladna SCO1 | F7: profikasa | G7: 46132 | H7: 0.3306713 | I7: 161000332 | J7: NE | K7: 21153398 | L7: 5900749618991 | M7: FS IMPORT- EXPORT s.r.o. | N7: 50201 | O7: BA! Energetická mysli tyči | P7: NE | R7: 11.4 | S7: =R7-T7 -> 10.178571 | T7: =R7*U7/(U7+100) -> 1.2214286 | U7: 12 | V7: 0 | W7: 1 | X7: KS | Y7: =R7*W7 -> 11.4 | Z7: =S7*W7 -> 10.178571 | AA7: =T7*W7 -> 1.2214286 | AB7: =V7*W7 -> 0 | AC7: =(R7+V7)*W7 -> 11.4 | AD7: 11.4 | AE7: 0 | AF7: 0
A8: CZ60738677 | B8: RAPO BRNO, s.r.o. | C8: 96 | D8: BALADA - Březinky | E8: Pokladna SCO1 | F8: profikasa | G8: 46132 | H8: 0.3306713 | I8: 161000332 | J8: NE | K8: 21153400 | L8: 5900749618984 | M8: FS IMPORT- EXPORT s.r.o. | N8: 50201 | O8: BA! Energy Bar brusinka 40 | P8: NE | R8: 11.4 | S8: =R8-T8 -> 10.178571 | T8: =R8*U8/(U8+100) -> 1.2214286 | U8: 12 | V8: 0 | W8: 1 | X8: KS | Y8: =R8*W8 -> 11.4 | Z8: =S8*W8 -> 10.178571 | AA8: =T8*W8 -> 1.2214286 | AB8: =V8*W8 -> 0 | AC8: =(R8+V8)*W8 -> 11.4 | AD8: 11.4 | AE8: 0 | AF8: 0
A9: CZ60738677 | B9: RAPO BRNO, s.r.o. | C9: 96 | D9: BALADA - Březinky | E9: Pokladna SCO1 | F9: profikasa | G9: 46132 | H9: 0.3306713 | I9: 161000332 | J9: NE | K9: 21153425 | L9: 5900749618939 | M9: FS IMPORT- EXPORT s.r.o. | N9: 50201 | O9: BA! 5 Dries fruits and nut | P9: NE | R9: 11.4 | S9: =R9-T9 -> 10.178571 | T9: =R9*U9/(U9+100) -> 1.2214286 | U9: 12 | V9: 0 | W9: 1 | X9: KS | Y9: =R9*W9 -> 11.4 | Z9: =S9*W9 -> 10.178571 | AA9: =T9*W9 -> 1.2214286 | AB9: =V9*W9 -> 0 | AC9: =(R9+V9)*W9 -> 11.4 | AD9: 11.4 | AE9: 0 | AF9: 0
A10: CZ60738677 | B10: RAPO BRNO, s.r.o. | C10: 96 | D10: BALADA - Březinky | E10: Pokladna SCO1 | F10: profikasa | G10: 46132 | H10: 0.3306713 | I10: 161000332 | J10: NE | K10: 60532961 | L10: 8596140001721 | M10: ČEPOS-Česká potravinářská obchodní a.s. | N10: 80306 | O10: Košilka ČC 50ks | P10: NE | R10: 1.9 | S10: =R10-T10 -> 1.5702479 | T10: =R10*U10/(U10+100) -> 0.32975207 | U10: 21 | V10: 0 | W10: 1 | X10: KS | Y10: =R10*W10 -> 1.9 | Z10: =S10*W10 -> 1.5702479 | AA10: =T10*W10 -> 0.32975207 | AB10: =V10*W10 -> 0 | AC10: =(R10+V10)*W10 -> 1.9 | AD10: 1.9 | AE10: 0 | AF10: 0
A11: CZ60738677 | B11: RAPO BRNO, s.r.o. | C11: 96 | D11: BALADA - Březinky | E11: Pokladna SCO1 | F11: profikasa | G11: 46132 | H11: 0.3306713 | I11: 161000332 | J11: NE | K11: 68356200 | L11: 287531 | M11: ČEROZFRUCHT České Budějovice | N11: 70202 | O11: Okurka hadovka | P11: NE | R11: 33.9 | S11: =R11-T11 -> 30.267857 | T11: =R11*U11/(U11+100) -> 3.6321429 | U11: 12 | V11: 0 | W11: 0.294 | X11: KG | Y11: =R11*W11 -> 9.9666 | Z11: =S11*W11 -> 8.89875 | AA11: =T11*W11 -> 1.06785 | AB11: =V11*W11 -> 0 | AC11: =(R11+V11)*W11 -> 9.9666 | AD11: 33.9 | AE11: 0 | AF11: 0
A12: CZ60738677 | B12: RAPO BRNO, s.r.o. | C12: 96 | D12: BALADA - Březinky | E12: Pokladna SCO1 | F12: profikasa | G12: 46132 | H12: 0.3306713 | I12: 161000332 | J12: NE | K12: 68356200 | L12: 287531 | M12: ČEROZFRUCHT České Budějovice | N12: 70202 | O12: Okurka hadovka | P12: NE | R12: 33.9 | S12: =R12-T12 -> 30.267857 | T12: =R12*U12/(U12+100) -> 3.6321429 | U12: 12 | V12: 0 | W12: 0.264 | X12: KG | Y12: =R12*W12 -> 8.9496 | Z12: =S12*W12 -> 7.9907143 | AA12: =T12*W12 -> 0.95888571 | AB12: =V12*W12 -> 0 | AC12: =(R12+V12)*W12 -> 8.9496 | AD12: 33.9 | AE12: 0 | AF12: 0
A13: CZ60738677 | B13: RAPO BRNO, s.r.o. | C13: 96 | D13: BALADA - Březinky | E13: Pokladna SCO1 | F13: profikasa | G13: 46132 | H13: 0.3306713 | I13: 161000332 | J13: NE | K13: 68356200 | L13: 287531 | M13: ČEROZFRUCHT České Budějovice | N13: 70202 | O13: Okurka hadovka | P13: NE | R13: 33.9 | S13: =R13-T13 -> 30.267857 | T13: =R13*U13/(U13+100) -> 3.6321429 | U13: 12 | V13: 0 | W13: 0.284 | X13: KG | Y13: =R13*W13 -> 9.6276 | Z13: =S13*W13 -> 8.5960714 | AA13: =T13*W13 -> 1.0315286 | AB13: =V13*W13 -> 0 | AC13: =(R13+V13)*W13 -> 9.6276 | AD13: 33.9 | AE13: 0 | AF13: 0
A14: CZ60738677 | B14: RAPO BRNO, s.r.o. | C14: 96 | D14: BALADA - Březinky | E14: Pokladna SCO1 | F14: profikasa | G14: 46132 | H14: 0.3580787 | I14: 161000333 | J14: NE | K14: 10103125 | L14: 8584004030000 | M14: I.D.C. Praha, a.s. | N14: 51001 | O14: Mila řezy 50g | P14: NE | R14: 18.9 | S14: =R14-T14 -> 16.875 | T14: =R14*U14/(U14+100) -> 2.025 | U14: 12 | V14: 0 | W14: 2 | X14: KS | Y14: =R14*W14 -> 37.8 | Z14: =S14*W14 -> 33.75 | AA14: =T14*W14 -> 4.05 | AB14: =V14*W14 -> 0 | AC14: =(R14+V14)*W14 -> 37.8 | AD14: 18.9 | AE14: 0 | AF14: 0
A15: CZ60738677 | B15: RAPO BRNO, s.r.o. | C15: 96 | D15: BALADA - Březinky | E15: Pokladna SCO1 | F15: profikasa | G15: 46132 | H15: 0.3580787 | I15: 161000333 | J15: NE | K15: 31775740 | L15: 4014500515083 | M15: Zott s.r.o. | N15: 20112 | O15: Zott Monte Snack 29g | P15: NE | R15: 11.9 | S15: =R15-T15 -> 10.625 | T15: =R15*U15/(U15+100) -> 1.275 | U15: 12 | V15: 0 | W15: 1 | X15: KS | Y15: =R15*W15 -> 11.9 | Z15: =S15*W15 -> 10.625 | AA15: =T15*W15 -> 1.275 | AB15: =V15*W15 -> 0 | AC15: =(R15+V15)*W15 -> 11.9 | AD15: 11.9 | AE15: 0 | AF15: 0
A16: CZ60738677 | B16: RAPO BRNO, s.r.o. | C16: 96 | D16: BALADA - Březinky | E16: Pokladna SCO1 | F16: profikasa | G16: 46132 | H16: 0.3580787 | I16: 161000333 | J16: NE | K16: 31775740 | L16: 4014500515083 | M16: Zott s.r.o. | N16: 20112 | O16: Zott Monte Snack 29g | P16: NE | R16: 11.9 | S16: =R16-T16 -> 10.625 | T16: =R16*U16/(U16+100) -> 1.275 | U16: 12 | V16: 0 | W16: 1 | X16: KS | Y16: =R16*W16 -> 11.9 | Z16: =S16*W16 -> 10.625 | AA16: =T16*W16 -> 1.275 | AB16: =V16*W16 -> 0 | AC16: =(R16+V16)*W16 -> 11.9 | AD16: 11.9 | AE16: 0 | AF16: 0
... A24: CZ60738677 | B24: RAPO BRNO, s.r.o. | C24: 96 | D24: BALADA - Březinky | E24: Pokladna SCO1 | F24: profikasa | G24: 46132 | H24: 0.38399306 | I24: 161000336 | J24: NE | K24: 31775791 | L24: 4014500520773 | M24: Zott s.r.o. | N24: 20101 | O24: Zott Protein Drink a přích | P24: NE | R24: 29.9 | S24: =R24-T24 -> 26.696429 | T24: =R24*U24/(U24+100) -> 3.2035714 | U24: 12 | V24: 0 | W24: 1 | X24: KS | Y24: =R24*W24 -> 29.9 | Z24: =S24*W24 -> 26.696429 | AA24: =T24*W24 -> 3.2035714 | AB24: =V24*W24 -> 0 | AC24: =(R24+V24)*W24 -> 29.9 | AD24: 29.9 | AE24: 0 | AF24: 0
A25: CZ60738677 | B25: RAPO BRNO, s.r.o. | C25: 96 | D25: BALADA - Březinky | E25: Pokladna SCO1 | F25: profikasa | G25: 46132 | H25: 0.38399306 | I25: 161000336 | J25: NE | K25: 45116303 | L25: 8594001026357 | M25: Mattoni 1873 a.s. | N25: 52202 | O25: Magnesia Plus Boost mandar | P25: ANO | Q25: BALADA 26_9A | R25: 24.9 | S25: =R25-T25 -> 20.578512 | T25: =R25*U25/(U25+100) -> 4.3214876 | U25: 21 | V25: 0 | W25: 1 | X25: KS | Y25: =R25*W25 -> 24.9 | Z25: =S25*W25 -> 20.578512 | AA25: =T25*W25 -> 4.3214876 | AB25: =V25*W25 -> 0 | AC25: =(R25+V25)*W25 -> 24.9 | AD25: 24.9 | AE25: 0 | AF25: 0
A26: CZ60738677 | B26: RAPO BRNO, s.r.o. | C26: 96 | D26: BALADA - Březinky | E26: Pokladna SCO1 | F26: profikasa | G26: 46132 | H26: 0.40315972 | I26: 161000337 | J26: NE | K26: 12103849 | L26: 8584004803307 | M26: I.D.C. Praha, a.s. | N26: 51101 | O26: Lina celomáčená tyčinka ch | P26: NE | R26: 27.9 | S26: =R26-T26 -> 24.910714 | T26: =R26*U26/(U26+100) -> 2.9892857 | U26: 12 | V26: 0 | W26: 1 | X26: KS | Y26: =R26*W26 -> 27.9 | Z26: =S26*W26 -> 24.910714 | AA26: =T26*W26 -> 2.9892857 | AB26: =V26*W26 -> 0 | AC26: =(R26+V26)*W26 -> 27.9 | AD26: 27.9 | AE26: 0 | AF26: 0
A27: CZ60738677 | B27: RAPO BRNO, s.r.o. | C27: 96 | D27: BALADA - Březinky | E27: Pokladna SCO1 | F27: profikasa | G27: 46132 | H27: 0.40315972 | I27: 161000337 | J27: NE | K27: 21153400 | L27: 5900749618984 | M27: FS IMPORT- EXPORT s.r.o. | N27: 50201 | O27: BA! Energy Bar brusinka 40 | P27: NE | R27: 11.4 | S27: =R27-T27 -> 10.178571 | T27: =R27*U27/(U27+100) -> 1.2214286 | U27: 12 | V27: 0 | W27: 1 | X27: KS | Y27: =R27*W27 -> 11.4 | Z27: =S27*W27 -> 10.178571 | AA27: =T27*W27 -> 1.2214286 | AB27: =V27*W27 -> 0 | AC27: =(R27+V27)*W27 -> 11.4 | AD27: 11.4 | AE27: 0 | AF27: 0
A28: CZ60738677 | B28: RAPO BRNO, s.r.o. | C28: 96 | D28: BALADA - Březinky | E28: Pokladna SCO1 | F28: profikasa | G28: 46132 | H28: 0.42946759 | I28: 161000338 | J28: NE | K28: 11309154 | L28: 8595606210059 | M28: INTERSNACK a.s. | N28: 50101 | O28: Bohemia chips slanina 60g | P28: NE | R28: 27.9 | S28: =R28-T28 -> 24.910714 | T28: =R28*U28/(U28+100) -> 2.9892857 | U28: 12 | V28: 0 | W28: 1 | X28: KS | Y28: =R28*W28 -> 27.9 | Z28: =S28*W28 -> 24.910714 | AA28: =T28*W28 -> 2.9892857 | AB28: =V28*W28 -> 0 | AC28: =(R28+V28)*W28 -> 27.9 | AD28: 27.9 | AE28: 0 | AF28: 0
A29: CZ60738677 | B29: RAPO BRNO, s.r.o. | C29: 96 | D29: BALADA - Březinky | E29: Pokladna SCO1 | F29: profikasa | G29: 46132 | H29: 0.42946759 | I29: 161000338 | J29: NE | K29: 11980030 | L29: 8594004160003 | M29: SECALO a.s. | N29: 50101 | O29: Křupky arašídové 60g | P29: NE | R29: 13.9 | S29: =R29-T29 -> 12.410714 | T29: =R29*U29/(U29+100) -> 1.4892857 | U29: 12 | V29: 0 | W29: 1 | X29: KS | Y29: =R29*W29 -> 13.9 | Z29: =S29*W29 -> 12.410714 | AA29: =T29*W29 -> 1.4892857 | AB29: =V29*W29 -> 0 | AC29: =(R29+V29)*W29 -> 13.9 | AD29: 13.9 | AE29: 0 | AF29: 0
A30: CZ60738677 | B30: RAPO BRNO, s.r.o. | C30: 96 | D30: BALADA - Březinky | E30: Pokladna SCO1 | F30: profikasa | G30: 46132 | H30: 0.42946759 | I30: 161000338 | J30: NE | K30: 31704300 | L30: 8594006320122 | M30: Moravia Lacto a.s. | N30: 20101 | O30: Mléko polotučné 1,5% Morav | P30: NE | R30: 27.9 | S30: =R30-T30 -> 24.910714 | T30: =R30*U30/(U30+100) -> 2.9892857 | U30: 12 | V30: 0 | W30: 1 | X30: KS | Y30: =R30*W30 -> 27.9 | Z30: =S30*W30 -> 24.910714 | AA30: =T30*W30 -> 2.9892857 | AB30: =V30*W30 -> 0 | AC30: =(R30+V30)*W30 -> 27.9 | AD30: 27.9 | AE30: 0 | AF30: 0
A31: CZ60738677 | B31: RAPO BRNO, s.r.o. | C31: 96 | D31: BALADA - Březinky | E31: Pokladna SCO1 | F31: profikasa | G31: 46132 | H31: 0.42946759 | I31: 161000338 | J31: NE | K31: 53121264 | L31: 8594404026428 | M31: Plzeňský Prazdroj, a.s. | N31: 52101 | O31: Birell příchuť Polotmavý C | P31: NE | R31: 23.9 | S31: =R31-T31 -> 19.752066 | T31: =R31*U31/(U31+100) -> 4.1479339 | U31: 21 | V31: 0 | W31: 1 | X31: KS | Y31: =R31*W31 -> 23.9 | Z31: =S31*W31 -> 19.752066 | AA31: =T31*W31 -> 4.1479339 | AB31: =V31*W31 -> 0 | AC31: =(R31+V31)*W31 -> 23.9 | AD31: 23.9 | AE31: 0 | AF31: 0
